Workbook

Sheet Original
D1: =HYPERLINK("#"&"Index!$A$1"&"","Home") -> Home | E1: A2. SUMMARY:[Website] Rate your agreement on statements related to Accessibility Service. | F1: Base: Who used Website | G1: Strongly Agree | H1: Agree | I1: Neutral | J1: Disagree | K1: Strongly Disagree | M1: Total | N1: Average | O1: T2B (4+5)
A2: A2. SUMMARY:[Website] Rate your agreement on statements related to Accessibility Service. | C2: It was easy to find the Ministry of Health and Prevention (MOHAP) contact number, website, or mobile app | F2: 0 | G2: - | H2: - | I2: - | J2: - | K2: - | L2: ____ | M2: - | N2: 0 | O2: -
C3: It is easy to find the service information | F3: 0 | G3: - | H3: - | I3: - | J3: - | K3: - | L3: ____ | M3: - | N3: 0 | O3: -
C4: There are several channels to facilitate service information access and delivery | F4: 0 | G4: - | H4: - | I4: - | J4: - | K4: - | L4: ____ | M4: - | N4: 0 | O4: -
C5: The website/mobile app is free of errors or technical problems | F5: 1000 | G5: 0.664 | H5: 0.21 | I5: 0.094 | J5: 0.02 | K5: 0.012 | L5: ____ | M5: 1 | N5: 4.5 | O5: 0.874
C6: The process was efficient, and I was not required to provide the same information more than once. | F6: 1000 | G6: 0.756 | H6: 0.164 | I6: 0.059 | J6: 0.01 | K6: 0.011 | L6: ____ | M6: 1 | N6: 4.6 | O6: 0.92
C7: It is easy to find and access MOHAP’s contact information and service details through different channels. | F7: 1000 | G7: 0.75 | H7: 0.16 | I7: 0.066 | J7: 0.011 | K7: 0.013 | L7: ____ | M7: 1 | N7: 4.6 | O7: 0.91
D9: =HYPERLINK("#"&"Index!$A$1"&"","Home") -> Home | E9: A2. SUMMARY:[Mobile App] Rate your agreement on statements related to Accessibility Service. | F9: Base: Who used Mobile channel | G9: Strongly Agree | H9: Agree | I9: Neutral | J9: Disagree | K9: Strongly Disagree | M9: Total | N9: Average | O9: T2B (4+5)
A10: A2. SUMMARY:[Mobile App] Rate your agreement on statements related to Accessibility Service. | C10: It was easy to find the Ministry of Health and Prevention (MOHAP) contact number, website, or mobile app | F10: 0 | G10: - | H10: - | I10: - | J10: - | K10: - | L10: ____ | M10: - | N10: 0 | O10: -
C11: It is easy to find the service information | F11: 0 | G11: - | H11: - | I11: - | J11: - | K11: - | L11: ____ | M11: - | N11: 0 | O11: -
C12: There are several channels to facilitate service information access and delivery | F12: 0 | G12: - | H12: - | I12: - | J12: - | K12: - | L12: ____ | M12: - | N12: 0 | O12: -
C13: The website/mobile app is free of errors or technical problems | F13: 1167 | G13: 0.67 | H13: 0.184 | I13: 0.102 | J13: 0.024 | K13: 0.02 | L13: ____ | M13: 1 | N13: 4.5 | O13: 0.854
C14: The process was efficient, and I was not required to provide the same information more than once. | F14: 1167 | G14: 0.782 | H14: 0.134 | I14: 0.06 | J14: 0.01 | K14: 0.014 | L14: ____ | M14: 1 | N14: 4.7 | O14: 0.916
C15: It is easy to find and access MOHAP’s contact information and service details through different channels. | F15: 1167 | G15: 0.786 | H15: 0.135 | I15: 0.057 | J15: 0.012 | K15: 0.01 | L15: ____ | M15: 1 | N15: 4.7 | O15: 0.92
D17: =HYPERLINK("#"&"Index!$A$1"&"","Home") -> Home | E17: A4A. SUMMARY:[Website] Rate your agreement on statements related to Information quality of Service | F17: Base: Who used Website | G17: Strongly Agree | H17: Agree | I17: Neutral | J17: Disagree | K17: Strongly Disagree | M17: Total | N17: Average | O17: T2B (4+5)
A18: #.A4A. SUMMARY:[Website] Rate your agreement on statements related to Information quality of Service | C18: The information obtained through service stages is clear and useful (email/SMS) | F18: 0 | G18: - | H18: - | I18: - | J18: - | K18: - | L18: ____ | M18: - | N18: 0 | O18: -
C19: I received adequate notifications throughout all stages of the service delivery | F19: 0 | G19: - | H19: - | I19: - | J19: - | K19: - | L19: ____ | M19: - | N19: 0 | O19: -
C20: The notifications and information received via email/SMS throughout all stages were clear, useful, and adequate | F20: 1000 | G20: 0.824 | H20: 0.116 | I20: 0.04 | J20: 0.013 | K20: 0.007 | L20: ____ | M20: 1 | N20: 4.7 | O20: 0.94
D22: =HYPERLINK("#"&"Index!$A$1"&"","Home") -> Home | E22: A4A. SUMMARY:[Mobile App] Rate your agreement on statements related to Information quality of Service | F22: Base: Who used Mobile App | G22: Strongly Agree | H22: Agree | I22: Neutral | J22: Disagree | K22: Strongly Disagree | M22: Total | N22: Average | O22: T2B (4+5)
A23: #.A4A. SUMMARY:[Mobile App] Rate your agreement on statements related to Information quality of Service | C23: The information obtained through service stages is clear and useful (email/SMS) | F23: 0 | G23: - | H23: - | I23: - | J23: - | K23: - | L23: ____ | M23: - | N23: 0 | O23: -
C24: I received adequate notifications throughout all stages of the service delivery | F24: 0 | G24: - | H24: - | I24: - | J24: - | K24: - | L24: ____ | M24: - | N24: 0 | O24: -
C25: The notifications and information received via email/SMS throughout all stages were clear, useful, and adequate | F25: 1167 | G25: 0.851 | H25: 0.093 | I25: 0.033 | J25: 0.011 | K25: 0.013 | L25: ____ | M25: 1 | N25: 4.8 | O25: 0.943
D27: =HYPERLINK("#"&"Index!$A$1"&"","Home") -> Home | E27: A6. SUMMARY:[Website] Rate your agreement on statements related to Ease of use Service. | F27: Base: Who used Website [Excluded NA] | G27: Strongly Agree | H27: Agree | I27: Neutral | J27: Disagree | K27: Strongly Disagree | M27: Total | N27: Average | O27: T2B (4+5)
A28: #.A6. SUMMARY:[Website] Rate your agreement on statements related to Ease of use Service. | C28: Ease of use Service: It is easy to make a payment for the service | F28: 955 | G28: 0.84 | H28: 0.092 | I28: 0.044 | J28: 0.014 | K28: 0.01 | L28: ____ | M28: 1 | N28: 4.7 | O28: 0.932
C29: Ease of use Service: In general, the service procedures are simple and easy | F29: 994 | G29: 0.815 | H29: 0.121 | I29: 0.047 | J29: 0.011 | K29: 0.006 | L29: ____ | M29: 1 | N29: 4.7 | O29: 0.936
C30: Ease of use Service: Service interface is appealing and user-friendly (Website & Mobile app) | F30: 996 | G30: 0.755 | H30: 0.159 | I30: 0.059 | J30: 0.017 | K30: 0.01 | L30: ____ | M30: 1 | N30: 4.6 | O30: 0.914
C31: Ease of use Service: Ease of tracking the status of your request | F31: 975 | G31: 0.747 | H31: 0.144 | I31: 0.07 | J31: 0.026 | K31: 0.014 | L31: ____ | M31: 1 | N31: 4.6 | O31: 0.89
C32: Ease of use Service: Ease of accessing technical support if needed | F32: 787 | G32: 0.694 | H32: 0.17 | I32: 0.078 | J32: 0.033 | K32: 0.025 | L32: ____ | M32: 1 | N32: 4.5 | O32: 0.864
C33: Ease of use Service: The service provided exceeded my expectations (in terms of ease, speed, accuracy, etc.). | F33: 0 | G33: - | H33: - | I33: - | J33: - | K33: - | L33: ____ | M33: - | N33: 0 | O33: -
D35: =HYPERLINK("#"&"Index!$A$1"&"","Home") -> Home | E35: A6. SUMMARY:[Mobile App] Rate your agreement on statements related to Ease of use Service. | F35: Base: Who used Mobile App [Excluded NA] | G35: Strongly Agree | H35: Agree | I35: Neutral | J35: Disagree | K35: Strongly Disagree | M35: Total | N35: Average | O35: T2B (4+5)
A36: #.A6. SUMMARY:[Mobile App] Rate your agreement on statements related to Ease of use Service. | C36: Ease of use Service: It is easy to make a payment for the service | F36: 1117 | G36: 0.839 | H36: 0.101 | I36: 0.035 | J36: 0.013 | K36: 0.013 | L36: ____ | M36: 1 | N36: 4.7 | O36: 0.94
C37: Ease of use Service: In general, the service procedures are simple and easy | F37: 1164 | G37: 0.827 | H37: 0.113 | I37: 0.038 | J37: 0.008 | K37: 0.014 | L37: ____ | M37: 1 | N37: 4.7 | O37: 0.941
C38: Ease of use Service: Service interface is appealing and user-friendly (Website & Mobile app) | F38: 1165 | G38: 0.797 | H38: 0.138 | I38: 0.044 | J38: 0.011 | K38: 0.01 | L38: ____ | M38: 1 | N38: 4.7 | O38: 0.935
C39: Ease of use Service: Ease of tracking the status of your request | F39: 1147 | G39: 0.776 | H39: 0.136 | I39: 0.058 | J39: 0.016 | K39: 0.015 | L39: ____ | M39: 1 | N39: 4.6 | O39: 0.912
C40: Ease of use Service: Ease of accessing technical support if needed | F40: 998 | G40: 0.72 | H40: 0.154 | I40: 0.08 | J40: 0.025 | K40: 0.02 | L40: ____ | M40: 1 | N40: 4.5 | O40: 0.875
C41: Ease of use Service: The service provided exceeded my expectations (in terms of ease, speed, accuracy, etc.). | F41: 0 | G41: - | H41: - | I41: - | J41: - | K41: - | L41: ____ | M41: - | N41: 0 | O41: -
D43: =HYPERLINK("#"&"Index!$A$1"&"","Home") -> Home | E43: A8. SUMMARY:[Website] Rate your agreement on statements related to Speed of service delivery | F43: Base: Who used Website[Excluded NA] | G43: Strongly Agree | H43: Agree | I43: Neutral | J43: Disagree | K43: Strongly Disagree | M43: Total | N43: Average | O43: T2B (4+5)
A44: #.A8. SUMMARY:[Website] Rate your agreement on statements related to Speed of service delivery | C44: Speed of service delivery - Submitting a service request, including filling out the required form, was completed within a reasonable time | F44: 0 | G44: - | H44: - | I44: - | J44: - | K44: - | L44: ____ | M44: - | N44: 0 | O44: -
C45: Speed of service delivery - The service was received within a reasonable time | F45: 0 | G45: - | H45: - | I45: - | J45: - | K45: - | L45: ____ | M45: - | N45: 0 | O45: -
C46: Speed of service delivery - Submitting the service request and receiving the service were completed within a reasonable time. | F46: 996 | G46: 0.77 | H46: 0.156 | I46: 0.046 | J46: 0.014 | K46: 0.014 | L46: ____ | M46: 1 | N46: 4.7 | O46: 0.926
...

Sheet Summary
A1: Update the numbers here | S1: # | T1: Overall | U1: Satisfaction | V1: Sample | W1: NPS | X1: Trust | Y1: Value | AA1: Customer Jouney
A2: Website - Summry Table | B2: Count | C2: 5 | D2: 4 | E2: 3 | F2: 2 | G2: 1 | H2: % | J2: Mobile App - Summry Table | K2: Count | L2: 5 | M2: 4 | N2: 3 | O2: 2 | P2: 1 | Q2: % | S2: 4 | T2: Mobile App | U2: =$Q$21 -> 0.93604444 | V2: =$K$20 -> 1167 | W2: =Original!V145 -> 0.77 | X2: =Original!$F$188 -> 0.973 | Y2: =Original!$F$174 -> 0.928 | AB2: Overall | AC2: Website | AD2: Mobile App | AF2: Customer Service Center
A3: A2. Rate your agreement on statements related to Accessibility Service. | B3: =Original!F1 -> Base: Who used Website | C3: =Original!G1 -> Strongly Agree | D3: =Original!H1 -> Agree | E3: =Original!I1 -> Neutral | F3: =Original!J1 -> Disagree | G3: =Original!K1 -> Strongly Disagree | H3: =AVERAGE(H4:H6) -> 0.90133333 | J3: A2. Rate your agreement on statements related to Accessibility Service. | K3: =Original!F9 -> Base: Who used Mobile channel | L3: =Original!G9 -> Strongly Agree | M3: =Original!H9 -> Agree | N3: =Original!I9 -> Neutral | O3: =Original!J9 -> Disagree | P3: =Original!K9 -> Strongly Disagree | Q3: =AVERAGE(Q4:Q6) -> 0.89666667 | S3: 3 | T3: Website | U3: =$H$21 -> 0.93458889 | V3: =$B$20 -> 1000 | W3: =Original!V144 -> 0.754 | X3: =Original!$E$188 -> 0.983 | Y3: =Original!$E$174 -> 0.906 | AA3: Getting service information | AB3: =AVERAGE(AG3,AD3,AC3) -> 0.9327 | AC3: =AVERAGE(AC4:AC5) -> 0.925 | AD3: =AVERAGE(AD4:AD5) -> 0.9315 | AF3: Getting service information | AG3: =AVERAGE(AG4:AG8) -> 0.9416
A4: A2D. Accessibility - The website/mobile app is free of errors or technical problems | B4: =Original!F5 -> 1000 | C4: =Original!G5 -> 0.664 | D4: =Original!H5 -> 0.21 | E4: =Original!I5 -> 0.094 | F4: =Original!J5 -> 0.02 | G4: =Original!K5 -> 0.012 | H4: =Original!O5 -> 0.874 | J4: A2D. Accessibility - The website/mobile app is free of errors or technical problems | K4: =Original!F13 -> 1167 | L4: =Original!G13 -> 0.67 | M4: =Original!H13 -> 0.184 | N4: =Original!I13 -> 0.102 | O4: =Original!J13 -> 0.024 | P4: =Original!K13 -> 0.02 | Q4: =Original!O13 -> 0.854 | S4: 2 | T4: Customer Service Center | U4: =$H$46 -> 0.925 | V4: =$B$39 -> 38 | W4: =Original!V143 -> 0.71 | X4: =Original!$D$188 -> 0.947 | Y4: =Original!$C$174 -> 0.845 | AA4: A2F. Accessibility - It is easy to find and access MOHAP’s contact information and service details through different channels. | AC4: =H6 -> 0.91 | AD4: =Q6 -> 0.92 | AF4: D1A. Rate of agreement related to the center - Easy of reaching the location using navigation maps | AG4: =H41 -> 0.946
A5: A2E. Accessibility - The process was efficient, and I was not required to provide the same information more than once. | B5: =Original!F6 -> 1000 | C5: =Original!G6 -> 0.756 | D5: =Original!H6 -> 0.164 | E5: =Original!I6 -> 0.059 | F5: =Original!J6 -> 0.01 | G5: =Original!K6 -> 0.011 | H5: =Original!O6 -> 0.92 | J5: A2E. Accessibility - The process was efficient, and I was not required to provide the same information more than once. | K5: =Original!F14 -> 1167 | L5: =Original!G14 -> 0.782 | M5: =Original!H14 -> 0.134 | N5: =Original!I14 -> 0.06 | O5: =Original!J14 -> 0.01 | P5: =Original!K14 -> 0.014 | Q5: =Original!O14 -> 0.916 | S5: 1 | T5: Call Center | U5: =$Q$40 -> 0.91707778 | V5: =$K$39 -> 515 | W5: =Original!V142 -> 0.694 | X5: =Original!$C$188 -> 0.95 | Y5: =Original!$D$174 -> 0.868 | AA5: A4C. Information quality: Th information received via email/SMS throughout all stages were clear, useful, and adequate | AC5: =H8 -> 0.94 | AD5: =Q8 -> 0.943 | AF5: D1B. Rate of agreement related to the center - Availability of adequate parking for customer | AG5: =H42 -> 0.879
A6: A2F. Accessibility - It is easy to find and access MOHAP’s contact information and service details through different channels. | B6: =Original!F7 -> 1000 | C6: =Original!G7 -> 0.75 | D6: =Original!H7 -> 0.16 | E6: =Original!I7 -> 0.066 | F6: =Original!J7 -> 0.011 | G6: =Original!K7 -> 0.013 | H6: =Original!O7 -> 0.91 | J6: A2F. Accessibility - It is easy to find and access MOHAP’s contact information and service details through different channels. | K6: =Original!F15 -> 1167 | L6: =Original!G15 -> 0.786 | M6: =Original!H15 -> 0.135 | N6: =Original!I15 -> 0.057 | O6: =Original!J15 -> 0.012 | P6: =Original!K15 -> 0.01 | Q6: =Original!O15 -> 0.92 | S6: 5 | T6: Email | U6: =$H$57 -> 0.870625 | V6: =$B$56 -> 281 | W6: =Original!V146 -> 0.577 | X6: =Original!$G$188 -> 0.922 | Y6: =Original!$G$174 -> 0.822 | AF6: D1C. Rate of agreement related to the center - Adequate and visible signages | AG6: =H43 -> 0.972
A7: A4A. Rate your agreement on statements related to Information quality of Service | B7: =Original!F17 -> Base: Who used Website | C7: =Original!G17 -> Strongly Agree | D7: =Original!H17 -> Agree | E7: =Original!I17 -> Neutral | F7: =Original!J17 -> Disagree | G7: =Original!K17 -> Strongly Disagree | H7: =AVERAGE(H8:H8) -> 0.94 | J7: A4A. Rate your agreement on statements related to Information quality of Service | K7: =Original!F22 -> Base: Who used Mobile App | L7: =Original!G22 -> Strongly Agree | M7: =Original!H22 -> Agree | N7: =Original!I22 -> Neutral | O7: =Original!J22 -> Disagree | P7: =Original!K22 -> Strongly Disagree | Q7: =AVERAGE(Q8:Q8) -> 0.943 | AF7: D1D. Rate of agreement related to the center - The branch provides ample facilities (prayer room, restrooms, vending machines…..) | AG7: =H44 -> 0.939
A8: A4C. Information quality: The notifications and information received via email/SMS throughout all stages were clear, useful, and adequate | B8: =Original!F20 -> 1000 | C8: =Original!G20 -> 0.824 | D8: =Original!H20 -> 0.116 | E8: =Original!I20 -> 0.04 | F8: =Original!J20 -> 0.013 | G8: =Original!K20 -> 0.007 | H8: =Original!O20 -> 0.94 | J8: A4C. Information quality: The notifications and information received via email/SMS throughout all stages were clear, useful, and adequate | K8: =Original!F25 -> 1167 | L8: =Original!G25 -> 0.851 | M8: =Original!H25 -> 0.093 | N8: =Original!I25 -> 0.033 | O8: =Original!J25 -> 0.011 | P8: =Original!K25 -> 0.013 | Q8: =Original!O25 -> 0.943 | T8: MOHAP Overall | U8: =AVERAGE(U2:U6) -> 0.91666722 | V8: =SUM(V2:V6) -> 3001 | W8: =Original!V141 -> 0.732 | X8: =Original!B188 -> 0.967 | Y8: =Original!B174 -> 0.896 | AF8: D1E. Rate of agreement related to the center - The self-service options (such as kiosk, website, and smart apps) were easy to use and helpful. | AG8: =H45 -> 0.972
A9: A6. Rate your agreement on statements related to Ease of use Service. | B9: =Original!F27 -> Base: Who used Website [Excluded NA] | C9: =Original!G27 -> Strongly Agree | D9: =Original!H27 -> Agree | E9: =Original!I27 -> Neutral | F9: =Original!J27 -> Disagree | G9: =Original!K27 -> Strongly Disagree | H9: =AVERAGE(H10:H14) -> 0.9072 | J9: A6. Rate your agreement on statements related to Ease of use Service. | K9: =Original!F35 -> Base: Who used Mobile App [Excluded NA] | L9: =Original!G35 -> Strongly Agree | M9: =Original!H35 -> Agree | N9: =Original!I35 -> Neutral | O9: =Original!J35 -> Disagree | P9: =Original!K35 -> Strongly Disagree | Q9: =AVERAGE(Q10:Q14) -> 0.9206
A10: A6A. Ease of use Service: It is easy to make a payment for the service | B10: =Original!F28 -> 955 | C10: =Original!G28 -> 0.84 | D10: =Original!H28 -> 0.092 | E10: =Original!I28 -> 0.044 | F10: =Original!J28 -> 0.014 | G10: =Original!K28 -> 0.01 | H10: =Original!O28 -> 0.932 | J10: A6A. Ease of use Service: It is easy to make a payment for the service | K10: =Original!F36 -> 1117 | L10: =Original!G36 -> 0.839 | M10: =Original!H36 -> 0.101 | N10: =Original!I36 -> 0.035 | O10: =Original!J36 -> 0.013 | P10: =Original!K36 -> 0.013 | Q10: =Original!O36 -> 0.94 | T10: Customer Jouney | V10: M | W10: W | X10: CS | AB10: Overall | AC10: Website | AD10: Mobile App | AF10: Customer Service Center
A11: A6B. Ease of use Service: In general, the service procedures are simple and easy | B11: =Original!F29 -> 994 | C11: =Original!G29 -> 0.815 | D11: =Original!H29 -> 0.121 | E11: =Original!I29 -> 0.047 | F11: =Original!J29 -> 0.011 | G11: =Original!K29 -> 0.006 | H11: =Original!O29 -> 0.936 | J11: A6B. Ease of use Service: In general, the service procedures are simple and easy | K11: =Original!F37 -> 1164 | L11: =Original!G37 -> 0.827 | M11: =Original!H37 -> 0.113 | N11: =Original!I37 -> 0.038 | O11: =Original!J37 -> 0.008 | P11: =Original!K37 -> 0.014 | Q11: =Original!O37 -> 0.941 | T11: Getting service information | U11: =AB3 -> 0.9327 | V11: =AD3 -> 0.9315 | W11: =AC3 -> 0.925 | X11: =AG3 -> 0.9416 | AA11: Applying for the service | AB11: =AVERAGE(AG11,AD11,AC11) -> 0.93076296 | AC11: =AVERAGE(AC12:AC16) -> 0.9356 | AD11: =AVERAGE(AD12:AD16) -> 0.9388 | AF11: Applying for the service | AG11: =AVERAGE(AG12:AG20) -> 0.91788889
A12: A6C. Ease of use Service: Service interface is appealing and user-friendly (Website & Mobile app) | B12: =Original!F30 -> 996 | C12: =Original!G30 -> 0.755 | D12: =Original!H30 -> 0.159 | E12: =Original!I30 -> 0.059 | F12: =Original!J30 -> 0.017 | G12: =Original!K30 -> 0.01 | H12: =Original!O30 -> 0.914 | J12: A6C. Ease of use Service: Service interface is appealing and user-friendly (Website & Mobile app) | K12: =Original!F38 -> 1165 | L12: =Original!G38 -> 0.797 | M12: =Original!H38 -> 0.138 | N12: =Original!I38 -> 0.044 | O12: =Original!J38 -> 0.011 | P12: =Original!K38 -> 0.01 | Q12: =Original!O38 -> 0.935 | T12: Applying for the service | U12: =AB11 -> 0.93076296 | V12: =AD11 -> 0.9388 | W12: =AC11 -> 0.9356 | X12: =AG11 -> 0.91788889 | AA12: A2E. Accessibility - The process was efficient, and I was not required to provide the same information more than once. | AC12: =H5 -> 0.92 | AD12: =Q5 -> 0.916 | AF12: B1A. Interaction with the staff - I was welcomed and provided with the necessary assistance | AG12: =H26 -> 0.974
A13: A6D. Ease of use Service: Ease of tracking the status of your request | B13: =Original!F31 -> 975 | C13: =Original!G31 -> 0.747 | D13: =Original!H31 -> 0.144 | E13: =Original!I31 -> 0.07 | F13: =Original!J31 -> 0.026 | G13: =Original!K31 -> 0.014 | H13: =Original!O31 -> 0.89 | J13: A6D. Ease of use Service: Ease of tracking the status of your request | K13: =Original!F39 -> 1147 | L13: =Original!G39 -> 0.776 | M13: =Original!H39 -> 0.136 | N13: =Original!I39 -> 0.058 | O13: =Original!J39 -> 0.016 | P13: =Original!K39 -> 0.015 | Q13: =Original!O39 -> 0.912 | T13: Interaction during processing | U13: =AB24 -> 0.91816667 | V13: =AD24 -> 0.91 | W13: =AC24 -> 0.898 | X13: =AG24 -> 0.9465 | AA13: A6B. Ease of use Service: In general, the service procedures are simple and easy | AC13: =H11 -> 0.936 | AD13: =Q11 -> 0.941 | AF13: B1B. Interaction with the staff - Sufficient information was given | AG13: =H27 -> 0.921
A14: A6E. Ease of use Service: Ease of accessing technical support if needed | B14: =Original!F32 -> 787 | C14: =Original!G32 -> 0.694 | D14: =Original!H32 -> 0.17 | E14: =Original!I32 -> 0.078 | F14: =Original!J32 -> 0.033 | G14: =Original!K32 -> 0.025 | H14: =Original!O32 -> 0.864 | J14: A6E. Ease of use Service: Ease of accessing technical support if needed | K14: =Original!F40 -> 998 | L14: =Original!G40 -> 0.72 | M14: =Original!H40 -> 0.154 | N14: =Original!I40 -> 0.08 | O14: =Original!J40 -> 0.025 | P14: =Original!K40 -> 0.02 | Q14: =Original!O40 -> 0.875 | T14: Completing the service | U14: =AB30 -> 0.92616667 | V14: =AD30 -> 0.93866667 | W14: =AC30 -> 0.93633333 | X14: =AG30 -> 0.9035 | AA14: A6C. Ease of use Service: Service interface is appealing and user-friendly (Website & Mobile app) | AC14: =H12 -> 0.914 | AD14: =Q12 -> 0.935 | AF14: B1F. Interaction with the staff - I was treated with respect & appreciation, reflecting an interaction characterized by politeness | AG14: =H29 -> 0.947
A15: A8. Rate your agreement on statements related to Speed of service delivery | B15: =Original!F43 -> Base: Who used Website[Excluded NA] | C15: =Original!G43 -> Strongly Agree | D15: =Original!H43 -> Agree | E15: =Original!I43 -> Neutral | F15: =Original!J43 -> Disagree | G15: =Original!K43 -> Strongly Disagree | H15: =AVERAGE(H16:H16) -> 0.926 | J15: A8. Rate your agreement on statements related to Speed of service delivery | K15: =Original!F48 -> Base: Who used Mobile App [Excluded NA] | L15: =Original!G48 -> Strongly Agree | M15: =Original!H48 -> Agree | N15: =Original!I48 -> Neutral | O15: =Original!J48 -> Disagree | P15: =Original!K48 -> Strongly Disagree | Q15: =AVERAGE(Q16:Q16) -> 0.922 | AA15: A8C. Submitting the service request were completed within a reasonable time. | AC15: =H16 -> 0.926 | AD15: =Q16 -> 0.922 | AF15: B1G.The employee demonstrated active listening and attentiveness, and showed a clear understanding of my request | AG15: =H30 -> 0.947
A16: A8C. Submitting the service request and receiving the service were completed within a reasonable time. | B16: =Original!F46 -> 996 | C16: =Original!G46 -> 0.77 | D16: =Original!H46 -> 0.156 | E16: =Original!I46 -> 0.046 | F16: =Original!J46 -> 0.014 | G16: =Original!K46 -> 0.014 | H16: =Original!O46 -> 0.926 | J16: A8C. Submitting the service request and receiving the service were completed within a reasonable time. | K16: =Original!F51 -> 1160 | L16: =Original!G51 -> 0.778 | M16: =Original!H51 -> 0.144 | N16: =Original!I51 -> 0.049 | O16: =Original!J51 -> 0.012 | P16: =Original!K51 -> 0.017 | Q16: =Original!O51 -> 0.922 | S16: # | T16: NPS | U16: =U1 -> Satisfaction | V16: =Original!S140 -> Promoter | W16: =Original!T140 -> Passive | X16: =Original!U140 -> detractors | Y16: =Original!V140 -> NPS | AA16: A10. Customer privacy- I am sure that my personal information provided to the Ministry of Health and Prevention (MOHAP) will remain confidential | AC16: =H18 -> 0.982 | AD16: =Q18 -> 0.98 | AF16: B1E. Interaction with the staff - The process was efficient, and I was not required to provide the same information more than once. | AG16: =H28 -> 0.868
A17: A10. Rate your agreement on statements related to customer privacy | B17: =Original!F53 -> Base: Who used Website [Excluded NA] | C17: =Original!G53 -> Strongly Agree | D17: =Original!H53 -> Agree | E17: =Original!I53 -> Neutral | F17: =Original!J53 -> Disagree | G17: =Original!K53 -> Strongly Disagree | H17: =AVERAGE(H18:H18) -> 0.982 | J17: A10. Rate your agreement on statements related to customer privacy | K17: =Original!F57 -> Base: Who used Mobile App [Excluded NA] | L17: =Original!G57 -> Strongly Agree | M17: =Original!H57 -> Agree | N17: =Original!I57 -> Neutral | O17: =Original!J57 -> Disagree | P17: =Original!K57 -> Strongly Disagree | Q17: =AVERAGE(Q18:Q18) -> 0.98 | S17: 4 | T17: Mobile App | U17: =$Q$21 -> 0.93604444 | V17: =Original!S145 -> 0.82 | W17: =Original!T145 -> 0.13 | X17: =Original!U145 -> 0.05 | Y17: =Original!V145 -> 0.77 | AF17: B3E. The staff you interacted with - Fairness in dealing | AG17: =H33 -> 0.919
A18: A10A. Customer privacy- I am sure that my personal information provided to the Ministry of Health and Prevention (MOHAP) will remain confidential | B18: =Original!F54 -> 987 | C18: =Original!G54 -> 0.908 | D18: =Original!H54 -> 0.074 | E18: =Original!I54 -> 0.012 | F18: =Original!J54 -> 0.002 | G18: =Original!K54 -> 0.004 | H18: =Original!O54 -> 0.982 | J18: A10A. Customer privacy- I am sure that my personal information provided to the Ministry of Health and Prevention (MOHAP) will remain confidential | K18: =Original!F58 -> 1153 | L18: =Original!G58 -> 0.918 | M18: =Original!H58 -> 0.062 | N18: =Original!I58 -> 0.013 | O18: =Original!J58 -> 0.002 | P18: =Original!K58 -> 0.005 | Q18: =Original!O58 -> 0.98 | S18: 3 | T18: Website | U18: =$H$21 -> 0.93458889 | V18: =Original!S144 -> 0.807 | W18: =Original!T144 -> 0.14 | X18: =Original!U144 -> 0.053 | Y18: =Original!V144 -> 0.754 | AF18: B3F. The staff you interacted with - Made an extra effort to help | AG18: =H34 -> 0.816
A19: A12. Please rate your overall happiness with the service | B19: =Original!C62 -> Website | C19: =Original!G61 -> Very Happy | D19: =Original!H61 -> Happy | E19: =Original!I61 -> Neutral | F19: =Original!J61 -> Unhappy | G19: =Original!K61 -> Very Unhappy | H19: =AVERAGE(H20) -> 0.951 | J19: A12. Please rate your overall happiness with the service | K19: =Original!C63 -> Mobile app | L19: =Original!G61 -> Very Happy | M19: =Original!H61 -> Happy | N19: =Original!I61 -> Neutral | O19: =Original!J61 -> Unhappy | P19: =Original!K61 -> Very Unhappy | Q19: =AVERAGE(Q20) -> 0.954 | S19: 2 | T19: Customer Service Center | U19: =$H$46 -> 0.925 | V19: =Original!S143 -> 0.789 | W19: =Original!T143 -> 0.132 | X19: =Original!U143 -> 0.079 | Y19: =Original!V143 -> 0.71 | AF19: B3G. The staff you interacted with - Flexibility in dealing | AG19: =H35 -> 0.895
A20: A12. Please rate your overall happiness with the service | B20: =Original!F62 -> 1000 | C20: =Original!G62 -> 0.773 | D20: =Original!H62 -> 0.178 | E20: =Original!I62 -> 0.03 | F20: =Original!J62 -> 0.013 | G20: =Original!K62 -> 0.006 | H20: =Original!O62 -> 0.951 | J20: A12. Please rate your overall happiness with the service | K20: =Original!F63 -> 1167 | L20: =Original!G63 -> 0.803 | M20: =Original!H63 -> 0.151 | N20: =Original!I63 -> 0.03 | O20: =Original!J63 -> 0.009 | P20: =Original!K63 -> 0.008 | Q20: =Original!O63 -> 0.954 | S20: 1 | T20: Call Center | U20: =$Q$40 -> 0.91707778 | V20: =Original!S142 -> 0.783 | W20: =Original!T142 -> 0.128 | X20: =Original!U142 -> 0.089 | Y20: =Original!V142 -> 0.694 | AF20: B3H. The staff you interacted with - Knowledge and reliability in their dealing | AG20: =H36 -> 0.974
A21: Avrage of A2 & A4A & A6 & A8 & A10 & A12 | H21: =AVERAGE(H19,H17,H15,H9,H7,H3) -> 0.93458889 | J21: Avrage of A2 & A4A & A6 & A8 & A10 & A12 | Q21: =AVERAGE(Q19,Q17,Q15,Q9,Q7,Q3) -> 0.93604444 | S21: 5 | T21: Email | U21: =$H$57 -> 0.870625 | V21: =Original!S146 -> 0.719 | W21: =Original!T146 -> 0.139 | X21: =Original!U146 -> 0.142 | Y21: =Original!V146 -> 0.577
T23: Total | U23: - | V23: =Original!S141 -> 0.799 | W23: =Original!T141 -> 0.134 | X23: =Original!U141 -> 0.067 | Y23: =Original!V141 -> 0.732 | AB23: Overall | AC23: Website | AD23: Mobile App | AF23: Customer Service Center
A24: Customer Service Center - Summry Table | B24: Count | C24: 5 | D24: 4 | E24: 3 | F24: 2 | G24: 1 | H24: % | J24: Call Center - Summry Table | K24: Count | L24: 5 | M24: 4 | N24: 3 | O24: 2 | P24: 1 | Q24: % | AA24: Interaction during processing | AB24: =AVERAGE(AG24,AD24,AC24) -> 0.91816667 | AC24: =AVERAGE(AC25:AC27) -> 0.898 | AD24: =AVERAGE(AD25:AD27) -> 0.91 | AF24: Interaction during processing | AG24: =AVERAGE(AG25:AG26) -> 0.9465
A25: B1A. Rate your agreement on statements related to your interaction with the staff | B25: =Original!F78 -> Base: Who used Customer service center | C25: =Original!G78 -> Strongly Agree | D25: =Original!H78 -> Agree | E25: =Original!I78 -> Neutral | F25: =Original!J78 -> Disagree | G25: =Original!K78 -> Strongly Disagree | H25: =AVERAGE(H26:H30) -> 0.9314 | J25: B1A. Rate your agreement on statements related to your interaction with the staff | K25: =Original!F69 -> Base: Who used Call center | L25: =Original!G69 -> Strongly Agree | M25: =Original!H69 -> Agree | N25: =Original!I69 -> Neutral | O25: =Original!J69 -> Disagree | P25: =Original!K69 -> Strongly Disagree | Q25: =AVERAGE(Q26:Q30) -> 0.9154 | S25: T2B (4+5) | T25: A14,B5,C5 | U25: Very Easy | V25: Easy | W25: Neutral | X25: Difficult | Y25: Very Difficult | AA25: A4C. Information quality: The notifications received via email/SMS throughout all stages were clear, useful, and adequate | AC25: =H8 -> 0.94 | AD25: =Q8 -> 0.943 | AF25: B1G.The employee demonstrated active listening and attentiveness, and showed a clear understanding of my the challenges I faced | AG25: =H30 -> 0.947
A26: B1A. Interaction with the staff - I was welcomed and provided with the necessary assistance | B26: =Original!F79 -> 38 | C26: =Original!G79 -> 0.789 | D26: =Original!H79 -> 0.184 | E26: =Original!I79 -> - | F26: =Original!J79 -> 0.026 | G26: =Original!K79 -> - | H26: =Original!O79 -> 0.974 | J26: B1A. Interaction with the staff - I was welcomed and provided with the necessary assistance | K26: =Original!F70 -> 515 | L26: =Original!G70 -> 0.817 | M26: =Original!H70 -> 0.13 | N26: =Original!I70 -> 0.033 | O26: =Original!J70 -> 0.006 | P26: =Original!K70 -> 0.014 | Q26: =Original!O70 -> 0.948 | S26: =Original!O67 -> 0.932 | T26: Mobile app | U26: =Original!G67 -> 0.785 | V26: =Original!H67 -> 0.147 | W26: =Original!I67 -> 0.05 | X26: =Original!J67 -> 0.005 | Y26: =Original!K67 -> 0.013 | AA26: A6D. Ease of use Service: Ease of tracking the status of your request | AC26: =H13 -> 0.89 | AD26: =Q13 -> 0.912 | AF26: B3B. The staff you interacted with - Using clear and easy-to-understand language | AG26: =H32 -> 0.946
A27: B1B. Interaction with the staff - Sufficient information was given | B27: =Original!F80 -> 38 | C27: =Original!G80 -> 0.763 | D27: =Original!H80 -> 0.158 | E27: =Original!I80 -> 0.026 | F27: =Original!J80 -> 0.026 | G27: =Original!K80 -> 0.026 | H27: =Original!O80 -> 0.921 | J27: B1B. Interaction with the staff - Sufficient information was given | K27: =Original!F71 -> 515 | L27: =Original!G71 -> 0.757 | M27: =Original!H71 -> 0.13 | N27: =Original!I71 -> 0.054 | O27: =Original!J71 -> 0.033 | P27: =Original!K71 -> 0.025 | Q27: =Original!O71 -> 0.887 | S27: =Original!O66 -> 0.935 | T27: Website | U27: =Original!G66 -> 0.749 | V27: =Original!H66 -> 0.186 | W27: =Original!I66 -> 0.047 | X27: =Original!J66 -> 0.009 | Y27: =Original!K66 -> 0.009 | AA27: A6E. Ease of use Service: Ease of accessing technical support if needed | AC27: =H14 -> 0.864 | AD27: =Q14 -> 0.875
A28: B1E. Interaction with the staff - The process was efficient, and I was not required to provide the same information more than once. | B28: =Original!F83 -> 38 | C28: =Original!G83 -> 0.711 | D28: =Original!H83 -> 0.158 | E28: =Original!I83 -> 0.079 | F28: =Original!J83 -> 0.026 | G28: =Original!K83 -> 0.026 | H28: =Original!O83 -> 0.868 | J28: B1E. Interaction with the staff - The process was efficient, and I was not required to provide the same information more than once. | K28: =Original!F74 -> 515 | L28: =Original!G74 -> 0.666 | M28: =Original!H74 -> 0.159 | N28: =Original!I74 -> 0.097 | O28: =Original!J74 -> 0.033 | P28: =Original!K74 -> 0.045 | Q28: =Original!O74 -> 0.825 | S28: =H39 -> 0.921 | T28: Customer Service Center | U28: =C39 -> 0.763 | V28: =D39 -> 0.158 | W28: =E39 -> 0.053 | X28: =F39 -> - | Y28: =G39 -> 0.026
A29: B1F. Interaction with the staff - I was treated with respect & appreciation, reflecting an interaction characterized by politeness | B29: =Original!F84 -> 38 | C29: =Original!G84 -> 0.868 | D29: =Original!H84 -> 0.079 | E29: =Original!I84 -> - | F29: =Original!J84 -> 0.026 | G29: =Original!K84 -> 0.026 | H29: =Original!O84 -> 0.947 | J29: B1F. Interaction with the staff - I was treated with respect & appreciation, reflecting an interaction characterized by politeness | K29: =Original!F75 -> 515 | L29: =Original!G75 -> 0.926 | M29: =Original!H75 -> 0.052 | N29: =Original!I75 -> 0.014 | O29: =Original!J75 -> 0.004 | P29: =Original!K75 -> 0.004 | Q29: =Original!O75 -> 0.979 | S29: =Q39 -> 0.909 | T29: Call Center | U29: =L39 -> 0.767 | V29: =M39 -> 0.142 | W29: =N39 -> 0.054 | X29: =O39 -> 0.021 | Y29: =P39 -> 0.016 | AB29: Overall | AC29: Website | AD29: Mobile App | AF29: Customer Service Center
A30: B1G.The employee demonstrated active listening and attentiveness, and showed a clear understanding of my request and the challenges I faced | B30: =Original!F85 -> 38 | C30: =Original!G85 -> 0.816 | D30: =Original!H85 -> 0.132 | E30: =Original!I85 -> 0.026 | F30: =Original!J85 -> - | G30: =Original!K85 -> 0.026 | H30: =Original!O85 -> 0.947 | J30: B1G.The employee demonstrated active listening and attentiveness, and showed a clear understanding of my request and the challenges I faced | K30: =Original!F76 -> 515 | L30: =Original!G76 -> 0.823 | M30: =Original!H76 -> 0.115 | N30: =Original!I76 -> 0.039 | O30: =Original!J76 -> 0.006 | P30: =Original!K76 -> 0.017 | Q30: =Original!O76 -> 0.938 | S30: =H56 -> 0.819 | T30: Email | U30: =C56 -> 0.673 | V30: =D56 -> 0.146 | W30: =E56 -> 0.082 | X30: =F56 -> 0.021 | Y30: =G56 -> 0.078 | AA30: Completing the service | AB30: =AVERAGE(AG30,AD30,AC30) -> 0.92616667 | AC30: =AVERAGE(AC31:AC33) -> 0.93633333 | AD30: =AVERAGE(AD31:AD33) -> 0.93866667 | AF30: Completing the service | AG30: =AVERAGE(AG31:AG32) -> 0.9035
A31: B3. Rate your agreement on statements related to the staff you interacted with (Customer service center) | B31: =Original!F99 -> Base: Who used Service center [Excluded NA] | C31: =Original!G99 -> Strongly Agree | D31: =Original!H99 -> Agree | E31: =Original!I99 -> Neutral | F31: =Original!J99 -> Disagree | G31: =Original!K99 -> Strongly Disagree | H31: =AVERAGE(H32:H37) -> 0.906 | J31: B3. Rate your agreement on statements related to the staff you interacted with (Call center) | K31: =Original!F87 -> Base: Who used Call Center [Excluded NA] | L31: =Original!G87 -> Strongly Agree | M31: =Original!H87 -> Agree | N31: =Original!I87 -> Neutral | O31: =Original!J87 -> Disagree | P31: =Original!K87 -> Strongly Disagree | Q31: =AVERAGE(Q32:Q37) -> 0.92683333 | AA31: A6A. Ease of use Service: It is easy to make a payment for the service | AC31: =H10 -> 0.932 | AD31: =Q10 -> 0.94 | AF31: B3J. The staff you interacted with - The employees worked together as a team to ensure my satisfaction (in case I interacted with more | AG31: =H37 -> 0.886
A32: B3B. The staff you interacted with - Using clear and easy-to-understand language | B32: =Original!F101 -> 37 | C32: =Original!G101 -> 0.919 | D32: =Original!H101 -> 0.027 | E32: =Original!I101 -> 0.027 | F32: =Original!J101 -> 0.027 | G32: =Original!K101 -> - | H32: =Original!O101 -> 0.946 | J32: B3L. The staff you interacted with - Using clear and easy-to-understand language | K32: =Original!F89 -> 513 | L32: =Original!G89 -> 0.893 | M32: =Original!H89 -> 0.084 | N32: =Original!I89 -> 0.016 | O32: =Original!J89 -> 0.004 | P32: =Original!K89 -> 0.004 | Q32: =Original!O89 -> 0.977 | AA32: A8C. Receiving the service were completed within a reasonable time. | AC32: =H16 -> 0.926 | AD32: =Q16 -> 0.922 | AF32: B5. Please rate your overall happiness with your interaction with the STAFF using a 5 point scalepy | AG32: =H39 -> 0.921
A33: B3E. The staff you interacted with - Fairness in dealing | B33: =Original!F104 -> 37 | C33: =Original!G104 -> 0.865 | D33: =Original!H104 -> 0.054 | E33: =Original!I104 -> 0.054 | F33: =Original!J104 -> - | G33: =Original!K104 -> 0.027 | H33: =Original!O104 -> 0.919 | J33: B3O. The staff you interacted with - Fairness in dealing | K33: =Original!F92 -> 510 | L33: =Original!G92 -> 0.882 | M33: =Original!H92 -> 0.075 | N33: =Original!I92 -> 0.024 | O33: =Original!J92 -> 0.004 | P33: =Original!K92 -> 0.016 | Q33: =Original!O92 -> 0.957 | U33: A16 | V33: # | W33: % | AA33: A12. Please rate your overall happiness with the service | AC33: =H20 -> 0.951 | AD33: =Q20 -> 0.954
A34: B3F. The staff you interacted with - Made an extra effort to help | B34: =Original!F105 -> 38 | C34: =Original!G105 -> 0.737 | D34: =Original!H105 -> 0.079 | E34: =Original!I105 -> 0.132 | F34: =Original!J105 -> 0.026 | G34: =Original!K105 -> 0.026 | H34: =Original!O105 -> 0.816 | J34: B3P. The staff you interacted with - Made an extra effort to help | K34: =Original!F93 -> 508 | L34: =Original!G93 -> 0.738 | M34: =Original!H93 -> 0.132 | N34: =Original!I93 -> 0.073 | O34: =Original!J93 -> 0.014 | P34: =Original!K93 -> 0.043 | Q34: =Original!O93 -> 0.87 | T34: Gender | U34: =Original!$V$148 -> Female | V34: =Original!$V$151 -> 1598 | W34: =Original!$V$160 -> 0.939
A35: B3G. The staff you interacted with - Flexibility in dealing | B35: =Original!F106 -> 38 | C35: =Original!G106 -> 0.789 | D35: =Original!H106 -> 0.105 | E35: =Original!I106 -> 0.079 | F35: =Original!J106 -> - | G35: =Original!K106 -> 0.026 | H35: =Original!O106 -> 0.895 | J35: B3Q. The staff you interacted with - Flexibility in dealing | K35: =Original!F94 -> 512 | L35: =Original!G94 -> 0.828 | M35: =Original!H94 -> 0.117 | N35: =Original!I94 -> 0.031 | O35: =Original!J94 -> 0.014 | P35: =Original!K94 -> 0.01 | Q35: =Original!O94 -> 0.945 | U35: =Original!$U$148 -> Male | V35: =Original!$U$151 -> 1403 | W35: =Original!$U$160 -> 0.924
A36: B3H. The staff you interacted with - Knowledge and reliability in their dealing | B36: =Original!F107 -> 38 | C36: =Original!G107 -> 0.763 | D36: =Original!H107 -> 0.211 | E36: =Original!I107 -> - | F36: =Original!J107 -> - | G36: =Original!K107 -> 0.026 | H36: =Original!O107 -> 0.974 | J36: B3R. The staff you interacted with - Knowledge and reliability in their dealing | K36: =Original!F95 -> 513 | L36: =Original!G95 -> 0.764 | M36: =Original!H95 -> 0.144 | N36: =Original!I95 -> 0.053 | O36: =Original!J95 -> 0.021 | P36: =Original!K95 -> 0.018 | Q36: =Original!O95 -> 0.908
A37: B3J. The staff you interacted with - The employees worked together as a team to ensure my satisfaction (in case I interacted with more | B37: =Original!F109 -> 35 | C37: =Original!G109 -> 0.829 | D37: =Original!H109 -> 0.057 | E37: =Original!I109 -> 0.029 | F37: =Original!J109 -> 0.029 | G37: =Original!K109 -> 0.057 | H37: =Original!O109 -> 0.886 | J37: B3T. The staff you interacted with - The employees worked together as a team to ensure my satisfaction (in case I interacted with more | K37: =Original!F97 -> 437 | L37: =Original!G97 -> 0.771 | M37: =Original!H97 -> 0.133 | N37: =Original!I97 -> 0.055 | O37: =Original!J97 -> 0.021 | P37: =Original!K97 -> 0.021 | Q37: =Original!O97 -> 0.904 | T37: Nationality | U37: =Original!$AC$148 -> Others | V37: =Original!$AC$151 -> 11 | W37: =Original!$AC$160 -> 1
A38: B5. Please rate your overall happiness with your interaction with the STAFF using a 5 point scalepy | B38: =Original!C113 -> Customer service center | C38: =Original!G111 -> Very Happy | D38: =Original!H111 -> Happy | E38: =Original!I111 -> Neutral | F38: =Original!J111 -> Unhappy | G38: =Original!K111 -> Very Unhappy | H38: =AVERAGE(H39) -> 0.921 | J38: B5. Please rate your overall happiness with your interaction with the STAFF using a 5 point scalepy | K38: =Original!C112 -> Call Center | L38: =Original!G111 -> Very Happy | M38: =Original!H111 -> Happy | N38: =Original!I111 -> Neutral | O38: =Original!J111 -> Unhappy | P38: =Original!K111 -> Very Unhappy | Q38: =AVERAGE(Q39) -> 0.909 | U38: =Original!$X$148 -> GCC National | V38: =Original!$X$151 -> 55 | W38: =Original!$X$160 -> 0.982
A39: B5. Please rate your overall happiness with your interaction with the STAFF using a 5 point scalepy | B39: =Original!F113 -> 38 | C39: =Original!G113 -> 0.763 | D39: =Original!H113 -> 0.158 | E39: =Original!I113 -> 0.053 | F39: =Original!J113 -> - | G39: =Original!K113 -> 0.026 | H39: =Original!O113 -> 0.921 | J39: B5. Please rate your overall happiness with your interaction with the STAFF using a 5 point scalepy | K39: =Original!F112 -> 515 | L39: =Original!G112 -> 0.767 | M39: =Original!H112 -> 0.142 | N39: =Original!I112 -> 0.054 | O39: =Original!J112 -> 0.021 | P39: =Original!K112 -> 0.016 | Q39: =Original!O112 -> 0.909 | U39: =Original!$W$148 -> UAE National | V39: =Original!$W$151 -> 1661 | W39: =Original!$W$160 -> 0.939
A40: D1A. Rate your agreement on statements related to the center you visited - Easy of reaching the location using navigation maps | B40: =Original!F115 -> Base: Who used Customer service center [Excluded NA] | C40: =Original!G115 -> Strongly Agree | D40: =Original!H115 -> Agree | E40: =Original!I115 -> Neutral | F40: =Original!J115 -> Disagree | G40: =Original!K115 -> Strongly Disagree | H40: =AVERAGE(H41:H45) -> 0.9416 | J40: Avrage of B1A & B3 (B3K,B3L,B3M,B3N,B3O,B3P,B3Q,B3R,B3S,B3TT) & B5 | Q40: =AVERAGE(Q25,Q31,Q38) -> 0.91707778 | U40: =Original!$AA$148 -> Asian Expat | V40: =Original!$AA$151 -> 555 | W40: =Original!$AA$160 -> 0.93
A41: D1A. Rate of agreement related to the center - Easy of reaching the location using navigation maps | B41: =Original!F116 -> 37 | C41: =Original!G116 -> 0.784 | D41: =Original!H116 -> 0.162 | E41: =Original!I116 -> 0.054 | F41: =Original!J116 -> - | G41: =Original!K116 -> - | H41: =Original!O116 -> 0.946 | U41: =Original!$Z$148 -> Arab Expat | V41: =Original!$Z$151 -> 673 | W41: =Original!$Z$160 -> 0.915
...

Sheet Services
A1: Servise | C1: Count | D1: %
A2: Healthcare Professional Evaluation | B2: =VLOOKUP(A2,[1]Sheet2!$D$2:$E$193,2,0) -> تقييم المهني الصحي | C2: 10 | D2: 1
A3: Issue License / Renew License for a Health Advertisement | B3: =VLOOKUP(A3,[1]Sheet2!$D$2:$E$193,2,0) -> إصدار ترخيص/ تجديد ترخيص إعلان صحي | C3: 7 | D3: 1
A4: Licensing of a Pharmaceutical Facility | B4: =VLOOKUP(A4,[1]Sheet2!$D$2:$E$193,2,0) -> ترخيص مؤسسة صيدلانية | C4: 5 | D4: 1
A5: Amend a Pharmaceutical Facility License | B5: =VLOOKUP(A5,[1]Sheet2!$D$2:$E$193,2,0) -> تعديل ترخيص مؤسسة صيدلانية | C5: 4 | D5: 1
A6: Licensing of Pharmacists | B6: =VLOOKUP(A6,[1]Sheet2!$D$2:$E$193,2,0) -> ترخيص مزاولة مهنة الصيدلة | C6: 4 | D6: 1
A7: Issue/Cancel Pharmacy Home Delivery Permit | B7: =VLOOKUP(A7,[1]Sheet2!$D$2:$E$193,2,0) -> إصدار / إلغاء تصريح صيدلية للتوصيل إلى المنزل | C7: 1 | D7: 1
A8: Cancellation of a License to Practice as a Pharmacist | B8: =VLOOKUP(A8,[1]Sheet2!$D$2:$E$193,2,0) -> الغاء الترخيص بمزاولة مهنة الصيدلة | C8: 1 | D8: 1
A9: Approval of Medical Leaves and The Leave of Patient’s Companion | B9: =VLOOKUP(A9,[1]Sheet2!$D$2:$E$193,2,0) -> اعتماد الاجازات المرضية وإجازة المرافق | C9: 107 | D9: 0.972
A10: Renewal of a License to Practice as a Pharmacist | B10: =VLOOKUP(A10,[1]Sheet2!$D$2:$E$193,2,0) -> تجديد ترخيص مزاولة مهنة الصيدلة | C10: 15 | D10: 0.933
A11: Attestation of Medical Leaves and Reports | B11: =VLOOKUP(A11,[1]Sheet2!$D$2:$E$193,2,0) -> تصديق الإجازات والتقارير الطبية | C11: 2005 | D11: 0.931
A12: Renewal of a Pharmaceutical Facility License | B12: =VLOOKUP(A12,[1]Sheet2!$D$2:$E$193,2,0) -> تجديد ترخيص مؤسسة صيدلانية | C12: 7 | D12: 0.857
